<?xml version="1.0" encoding="utf-8"?>

<robot name="manipulator">
  <!-- ################# Defining the colors used in this robot ################# -->
  <material name="black">
    <color rgba="0 0 0 1.0"/>
  </material>
  <material name="flat_black">
    <color rgba="0.1 0.1 0.1 1.0"/>
  </material>
  <material name="dark_grey">
    <color rgba="0.175 0.175 0.175 1.0"/>
  </material>
  <material name="grey">
    <color rgba="0.3 0.3 0.3 1"/>
  </material>
  <material name="white">
    <color rgba="1 1 1 1"/>
  </material>
  <material name="gray">
    <color rgba="0.4 0.4 0.4 1"/>
  </material>
  <material name="silver">
    <color rgba="0.5 0.5 0.5 1"/>
  </material>
  <material name="Black">
    <color rgba="0.0 0.0 0.0 1.0"/>
  </material>
  <!-- ################# base_footprint ################# -->
  <link name="base_footprint">
    <visual>
      <origin rpy="0 0 0" xyz="0 0 0"/>
      <geometry>
        <box size="0.001 0.001 0.001"/>
      </geometry>
    </visual>
  </link>
  <!-- ################# base_link ################# -->
  <link name="base_link">
    <!-- <inertial>
	  <mass value="1" />
      <origin xyz="0 0 0.1" />
      <inertia ixx="0.05" ixy="0" ixz="0" iyy="0.05" iyz="0" izz="0.2" />
	</inertial> -->
    <visual>
      <origin rpy="0 0 0" xyz="0 0 0"/>
      <geometry>
        <mesh filename="package://robot_description/meshes/bulldog/base_link.stl"/>
      </geometry>
      <material name="flat_black"/>
    </visual>
    <collision>
      <origin rpy="0 0 0" xyz="0 0 0.1625"/>
      <geometry>
        <box size="0.85 0.42 0.325"/>
      </geometry>
    </collision>
  </link>
  <!-- ################# inertial_link ################# -->
  <link name="inertial_link">
    <inertial>
      <mass value="40"/>
      <origin xyz="0 0 0.1"/>
      <inertia ixx="0.7" ixy="-0.03" ixz="-0.15" iyy="2" iyz="-0.01" izz="4"/>
    </inertial>
  </link>
  <!-- ################# top_plate_link ################# -->
  <link name="top_plate_link">
    <inertial>
      <mass value="5" />
      <origin xyz="0 0 0.1" />
      <inertia ixx="0.5" ixy="0" ixz="0" iyy="0.5" iyz="0" izz="1" />
    </inertial>
    <visual>
      <origin rpy="0 0 0" xyz="0 0 0"/>
      <geometry>
        <mesh filename="package://robot_description/meshes/bulldog/top_plate.stl"/>
      </geometry>
      <material name="grey"/>
    </visual>
    <collision>
      <origin rpy="0 0 0" xyz="0 0 0"/>
      <geometry>
        <mesh filename="package://robot_description/meshes/bulldog/top_plate.stl"/>
      </geometry>
    </collision>
  </link>
  <!-- ################# rslidar ################# -->
  <link name="rslidar_link">
    <origin rpy="0 0 0" xyz="0 0 0"/>
    <visual>
      <geometry>
        <mesh filename="package://robot_description/meshes/rslidar/rslidar.dae"/>
      </geometry>
      <material name="black"/>
    </visual>
    <collision>
      <origin rpy="0 0 0" xyz="0 0 0"/>
      <geometry>
        <mesh filename="package://robot_description/meshes/rslidar/rslidar.stl"/>
      </geometry>
    </collision>
    <inertial>
      <mass value="0.564"/>
      <origin xyz="0 0 0"/>
      <inertia ixx="0.003881243" ixy="0.0" ixz="0.0" iyy="0.000498940" iyz="0.0" izz="0.003879257"/>
    </inertial>
  </link>
  <!-- ################# left_front_wheel_link ################# -->
  <link name="left_front_wheel_link">
    <inertial>
      <mass value="3"/>
      <origin xyz="0 0 0"/>
      <inertia ixx="0.025" ixy="0" ixz="0" iyy="0.025" iyz="0" izz="0.045"/>
    </inertial>
    <visual>
      <origin rpy="0 0 0" xyz="0 0 0"/>
      <geometry>
        <mesh filename="package://robot_description/meshes/bulldog/wheel.stl"/>
      </geometry>
      <material name="dark_grey"/>
    </visual>
    <collision>
      <origin rpy="1.5707963267949 0 0" xyz="0 0 0"/>
      <geometry>
        <cylinder length="0.142" radius="0.183"/>
      </geometry>
    </collision>
  </link>
  <!-- ################# right_front_wheel_link ################# -->
  <link name="right_front_wheel_link">
    <inertial>
      <mass value="3"/>
      <origin xyz="0 0 0"/>
      <inertia ixx="0.025" ixy="0" ixz="0" iyy="0.025" iyz="0" izz="0.045"/>
    </inertial>
    <visual>
      <origin rpy="0 0 0" xyz="0 0 0"/>
      <geometry>
        <mesh filename="package://robot_description/meshes/bulldog/wheel.stl"/>
      </geometry>
      <material name="dark_grey"/>
    </visual>
    <collision>
      <origin rpy="1.5707963267949 0 0" xyz="0 0 0"/>
      <geometry>
        <cylinder length="0.142" radius="0.183"/>
      </geometry>
    </collision>
  </link>
  <!-- ################# left_rear_wheel_link ################# -->
  <link name="left_rear_wheel_link">
    <inertial>
      <mass value="3"/>
      <origin xyz="0 0 0"/>
      <inertia ixx="0.025" ixy="0" ixz="0" iyy="0.025" iyz="0" izz="0.045"/>
    </inertial>
    <visual>
      <origin rpy="0 0 0" xyz="0 0 0"/>
      <geometry>
        <mesh filename="package://robot_description/meshes/bulldog/wheel.stl"/>
      </geometry>
      <material name="dark_grey"/>
    </visual>
    <collision>
      <origin rpy="1.5707963267949 0 0" xyz="0 0 0"/>
      <geometry>
        <cylinder length="0.142" radius="0.183"/>
      </geometry>
    </collision>
  </link>
  <!-- ################# right_rear_wheel_link ################# -->
  <link name="right_rear_wheel_link">
    <inertial>
      <mass value="3"/>
      <origin xyz="0 0 0"/>
      <inertia ixx="0.025" ixy="0" ixz="0" iyy="0.025" iyz="0" izz="0.045"/>
    </inertial>
    <visual>
      <origin rpy="0 0 0" xyz="0 0 0"/>
      <geometry>
        <mesh filename="package://robot_description/meshes/bulldog/wheel.stl"/>
      </geometry>
      <material name="dark_grey"/>
    </visual>
    <collision>
      <origin rpy="1.5707963267949 0 0" xyz="0 0 0"/>
      <geometry>
        <cylinder length="0.142" radius="0.183"/>
      </geometry>
    </collision>
  </link>
  <!-- ################# installation_plate_link ################# -->
  <link name="installation_plate_link">
    <visual>
      <origin rpy="0 0 0" xyz="0 0 0"/>
      <geometry>
        <mesh filename="package://robot_description/meshes/bulldog/installation_plate.stl"/>
      </geometry>
      <material name="black"/>
    </visual>
    <collision>
      <origin rpy="0 0 0" xyz="0 0 0"/>
      <geometry>
        <mesh filename="package://robot_description/meshes/bulldog/installation_plate.stl"/>
      </geometry>
    </collision>
  </link>
  <!-- ################# laser_link ################# -->
  <link name="laser_link"/>
  <!-- ################# box_link ################# -->
  <link name="box_link">
    <collision>
      <origin rpy="0 0 0" xyz="0 0 0"/>
      <geometry>
        <box size="0.32 0.4 0.15"/>
      </geometry>
    </collision>
    <visual>
      <origin rpy="0 0 0" xyz="0 0 0"/>
      <geometry>
        <box size="0.32 0.4 0.15"/>
      </geometry>
      <material name="grey"/>
    </visual>
    <inertial>
      <mass value="10"/>
      <origin rpy="0 0 0" xyz="0 0 0"/>
      <inertia ixx="0.5" ixy="0" ixz="0" iyy="0.5" iyz="0" izz="0.5"/>
    </inertial>
  </link>

  <joint name="base_footprint_joint" type="fixed">
    <origin rpy="0 0 0" xyz="0 0 0.1407"/>
    <parent link="base_footprint"/>
    <child link="base_link"/>
  </joint>

  <joint name="inertial_joint" type="fixed">
    <origin rpy="0 0 0" xyz="0 0 0"/>
    <parent link="base_link"/>
    <child link="inertial_link"/>
  </joint>

  <joint name="top_plate_joint" type="fixed">
    <origin rpy="0 0 0" xyz="0.07937 0 0.253"/>
    <parent link="base_link"/>
    <child link="top_plate_link"/>
  </joint>

  <joint name="rslidar_joint" type="fixed">
    <origin rpy="0 0 0" xyz="0.45 0 0.2"/>
    <parent link="base_link"/>
    <child link="rslidar_link"/>
    <axis xyz="0 1 0"/>
  </joint>

  <joint name="left_front_wheel_joint" type="continuous">
    <parent link="base_link"/>
    <child link="left_front_wheel_link"/>
    <origin rpy="0 0 0" xyz="0.27937 0.285 0.0435"/>
    <axis rpy="0 0 0" xyz="0 1 0"/>
    <!-- <dynamics damping="0.5" friction="1.0"/> -->
  </joint>

  <joint name="right_front_wheel_joint" type="continuous">
    <parent link="base_link"/>
    <child link="right_front_wheel_link"/>
    <origin rpy="0 0 0" xyz="0.27937 -0.285 0.0435"/>
    <axis rpy="0 0 0" xyz="0 1 0"/>
  </joint>

  <joint name="left_rear_wheel_joint" type="continuous">
    <parent link="base_link"/>
    <child link="left_rear_wheel_link"/>
    <origin rpy="0 0 0" xyz="-0.27937 0.285 0.0435"/>
    <axis rpy="0 0 0" xyz="0 1 0"/>
  </joint>

  <joint name="right_rear_wheel_joint" type="continuous">
    <parent link="base_link"/>
    <child link="right_rear_wheel_link"/>
    <origin rpy="0 0 0" xyz="-0.27937 -0.285 0.0435"/>
    <axis rpy="0 0 0" xyz="0 1 0"/>
  </joint>

  <joint name="installation_plate_joint" type="fixed">
    <parent link="base_link"/>
    <child link="installation_plate_link"/>
    <origin rpy="0 0 0" xyz="0.197 0 0.314"/>
  </joint>

  <joint name="laser_joint" type="fixed">
    <origin rpy="0 0 0" xyz="0.05 0 -0.2"/>
    <parent link="rslidar_link"/>
    <child link="laser_link"/>
  </joint>

  <joint name="box_joint" type="fixed">
    <axis xyz="0 1 0"/>
    <origin rpy="0 0 0" xyz="-0.15 0 0.395"/>
    <parent link="base_link"/>
    <child link="box_link"/>
  </joint>

  <!-- ################# panda_link0 ################# -->
  <link name="panda_link0">
    <visual>
      <geometry>
        <mesh filename="package://robot_description/meshes/panda/visual/link0.dae"/>
      </geometry>
      <material name="gray"/>
    </visual>
    <collision>
      <geometry>
        <mesh filename="package://robot_description/meshes/panda/collision/link0.stl"/>
      </geometry>
    </collision>
    <inertial>
      <origin rpy="0 0 0" xyz="0 0 -0.1750"/>
      <mass value="5"/>
      <inertia ixx="7.0337e-01" ixy="-1.3900e-04" ixz="6.7720e-03" iyy="7.0661e-01" iyz="1.9169e-02" izz="9.1170e-03"/>
    </inertial>
  </link>

  <!-- ################# panda_link1 ################# -->
  <link name="panda_link1">
    <visual>
      <geometry>
        <mesh filename="package://robot_description/meshes/panda/visual/link1.dae"/>
      </geometry>
      <material name="white"/>
    </visual>
    <collision>
      <geometry>
        <mesh filename="package://robot_description/meshes/panda/collision/link1.stl"/>
      </geometry>
    </collision>
    <inertial>
      <origin rpy="0 0 0" xyz="3.875e-03 2.081e-03 -0.1750"/>
      <mass value="4.970684"/>
      <inertia ixx="7.0337e-01" ixy="-1.3900e-04" ixz="6.7720e-03" iyy="7.0661e-01" iyz="1.9169e-02" izz="9.1170e-03"/>
    </inertial>
  </link>

  <!-- ################# panda_link2 ################# -->
  <link name="panda_link2">
    <visual>
      <geometry>
        <mesh filename="package://robot_description/meshes/panda/visual/link2.dae"/>
      </geometry>
      <material name="white"/>
    </visual>
    <collision>
      <geometry>
        <mesh filename="package://robot_description/meshes/panda/collision/link2.stl"/>
      </geometry>
    </collision>
    <inertial>
      <origin rpy="0 0 0" xyz="-3.141e-03 -2.872e-02 3.495e-03"/>
      <mass value="0.646926"/>
      <inertia ixx="7.9620e-03" ixy="-3.9250e-03" ixz="1.0254e-02" iyy="2.8110e-02" iyz="7.0400e-04" izz="2.5995e-02"/>
    </inertial>
  </link>

  <!-- ################# panda_link3 ################# -->
  <link name="panda_link3">
    <visual>
      <geometry>
        <mesh filename="package://robot_description/meshes/panda/visual/link3.dae"/>
      </geometry>
      <material name="white"/>
    </visual>
    <collision>
      <geometry>
        <mesh filename="package://robot_description/meshes/panda/collision/link3.stl"/>
      </geometry>
    </collision>
    <inertial>
      <origin rpy="0 0 0" xyz="2.7518e-02 3.9252e-02 -6.6502e-02"/>
      <mass value="3.228604"/>
      <inertia ixx="3.7242e-02" ixy="-4.7610e-03" ixz="-1.1396e-02" iyy="3.6155e-02" iyz="-1.2805e-02" izz="1.0830e-02"/>
    </inertial>
  </link>

  <!-- ################# panda_link4 ################# -->
  <link name="panda_link4">
    <visual>
      <geometry>
        <mesh filename="package://robot_description/meshes/panda/visual/link4.dae"/>
      </geometry>
      <material name="white"/>
    </visual>
    <collision>
      <geometry>
        <mesh filename="package://robot_description/meshes/panda/collision/link4.stl"/>
      </geometry>
    </collision>
    <inertial>
      <origin rpy="0 0 0" xyz="-5.317e-02 1.04419e-01 2.7454e-02"/>
      <mass value="3.587895"/>
      <inertia ixx="2.5853e-02" ixy="7.7960e-03" ixz="-1.3320e-03" iyy="1.9552e-02" iyz="8.6410e-03" izz="2.8323e-02"/>
    </inertial>
  </link>

  <!-- ################# panda_link5 ################# -->
  <link name="panda_link5">
    <visual>
      <geometry>
        <mesh filename="package://robot_description/meshes/panda/visual/link5.dae"/>
      </geometry>
      <material name="white"/>
    </visual>
    <collision>
      <geometry>
        <mesh filename="package://robot_description/meshes/panda/collision/link5.stl"/>
      </geometry>
    </collision>
    <inertial>
      <origin rpy="0 0 0" xyz="-1.1953e-02 4.1065e-02 -3.8437e-02"/>
      <mass value="1.225946"/>
      <inertia ixx="3.5549e-02" ixy="-2.1170e-03" ixz="-4.0370e-03" iyy="2.9474e-02" iyz="2.2900e-04" izz="8.6270e-03"/>
    </inertial>
  </link>

  <!-- ################# panda_link6 ################# -->
  <link name="panda_link6">
    <visual>
      <geometry>
        <mesh filename="package://robot_description/meshes/panda/visual/link6.dae"/>
      </geometry>
      <material name="white"/>
    </visual>
    <collision>
      <geometry>
        <mesh filename="package://robot_description/meshes/panda/collision/link6.stl"/>
      </geometry>
    </collision>
    <inertial>
      <origin rpy="0 0 0" xyz="6.0149e-02 -1.4117e-02 -1.0517e-02"/>
      <mass value="1.666555"/>
      <inertia ixx="1.9640e-03" ixy="1.0900e-04" ixz="-1.1580e-03" iyy="4.3540e-03" iyz="3.4100e-04" izz="5.4330e-03"/>
    </inertial>
  </link>

  <!-- ################# panda_link7 ################# -->
  <link name="panda_link7">
    <visual>
      <geometry>
        <mesh filename="package://robot_description/meshes/panda/visual/link7.dae"/>
      </geometry>
      <material name="gray"/>
    </visual>
    <collision>
      <geometry>
        <mesh filename="package://robot_description/meshes/panda/collision/link7.stl"/>
      </geometry>
    </collision>
    <inertial>
      <origin rpy="0 -0.7854 0" xyz="1.0517e-02 -4.252e-03 6.1597e-02"/>
      <mass value="7.35522e-01"/>
      <inertia ixx="1.2516e-02" ixy="-4.2800e-04" ixz="-1.1960e-03" iyy="1.0027e-02" iyz="-7.4100e-04" izz="4.8150e-03"/>
    </inertial>
  </link>

  <!-- ################# panda_link8 ################# -->
  <link name="panda_link8">
    <inertial>
      <origin rpy="0 -0.7854 0" xyz="0 0 0"/>
      <mass value="0.0"/>
      <inertia ixx="0.001" ixy="0.0" ixz="0.0" iyy="0.001" iyz="0.0" izz="0.001"/>
    </inertial>
  </link>

  <!-- ################# panda_hand ################# -->
  <link name="panda_hand">
    <visual>
      <geometry>
        <mesh filename="package://robot_description/meshes/panda/visual/hand.dae"/>
      </geometry>
    </visual>
    <collision>
      <geometry>
        <mesh filename="package://robot_description/meshes/panda/collision/hand.stl"/>
      </geometry>
    </collision>
    <inertial>
      <origin rpy="0 0 0" xyz="0 0 0"/>
      <mass value="0.68"/>
      <inertia ixx="0.1" ixy="0.0" ixz="0.0" iyy="0.1" iyz="0.0" izz="0.1"/>
    </inertial>
  </link>

  <!-- ################# gripper_frame ################# -->
  <link name="gripper_frame"/>

  <!-- ################# panda_leftfinger ################# -->
  <link name="panda_leftfinger">
    <visual>
      <geometry>
        <mesh filename="package://robot_description/meshes/panda/visual/finger.dae"/>
      </geometry>
    </visual>
    <collision>
      <geometry>
        <mesh filename="package://robot_description/meshes/panda/collision/finger.stl"/>
      </geometry>
    </collision>
    <inertial>
      <origin rpy="0 0 0" xyz="0 0 0"/>
      <mass value="0.01"/>
      <inertia ixx="0.1" ixy="0.0" ixz="0.0" iyy="0.1" iyz="0.0" izz="0.1"/>
    </inertial>
  </link>

  <!-- ################# panda_rightfinger ################# -->
  <link name="panda_rightfinger">
    <visual>
      <origin rpy="0 0 3.1416" xyz="0 0 0"/>
      <geometry>
        <mesh filename="package://robot_description/meshes/panda/visual/finger.dae"/>
      </geometry>
    </visual>
    <collision>
      <origin rpy="0 0 3.1416" xyz="0 0 0"/>
      <geometry>
        <mesh filename="package://robot_description/meshes/panda/collision/finger.stl"/>
      </geometry>
    </collision>
    <inertial>
      <origin rpy="0 0 0" xyz="0 0 0"/>
      <mass value="0.01"/>
      <inertia ixx="0.1" ixy="0.0" ixz="0.0" iyy="0.1" iyz="0.0" izz="0.1"/>
    </inertial>
  </link>

  <!-- ################# camera_link ################# -->
  <link name="camera_link">
    <inertial>
      <origin rpy="0 0 0" xyz="0 0 0"/>
      <mass value="0.1"/>
      <inertia ixx="0.01" ixy="0.0" ixz="0.0" iyy="0.01" iyz="0.0" izz="0.01"/>
    </inertial>
    <visual>
      <origin rpy="0 0 0" xyz="0 0 0"/>
      <geometry>
        <mesh filename="package://robot_description/meshes/Intel/d435.dae"/>
      </geometry>
    </visual>
    <collision>
      <origin rpy="0 0 0" xyz="0.0 0.0 0.0"/>
      <geometry>
        <mesh filename="package://robot_description/meshes/Intel/d435.dae"/>
      </geometry>
    </collision>
  </link>

  <!-- ################# Intel D435 rgb Frame ################# -->
  <link name="Intel_rgb_camera_link"/>

  <!-- ################# camera_link_fake ################# -->
  <link name="camera_link_fake"/>

  <joint name="bulldog_to_panda_joint" type="fixed">
    <parent link="base_link"/>
    <child link="panda_link0"/>
    <!-- <origin xyz="0.045 0.0 0.005" rpy="0 0 0"/> -->
    <origin xyz="0.242 0.0 0.324" rpy="0 0 0"/>
  </joint>

  <joint name="panda_joint1" type="revolute">
    <origin rpy="0 0 0" xyz="0 0 0.333"/>
    <parent link="panda_link0"/>
    <child link="panda_link1"/>
    <axis xyz="0 0 1"/>
    <limit effort="87" lower="-2.8973" upper="2.8973" velocity="2.1750"/>
    <dynamics damping="10.0" friction="5.0"/>
  </joint>

  <joint name="panda_joint2" type="revolute">
    <origin rpy="-1.57079632679 0 0" xyz="0 0 0"/>
    <parent link="panda_link1"/>
    <child link="panda_link2"/>
    <axis xyz="0 0 1"/>
    <limit effort="87" lower="-1.7628" upper="1.7628" velocity="2.1750"/>
    <dynamics damping="5.0" friction="2.0"/>
  </joint>

  <joint name="panda_joint3" type="revolute">
    <origin rpy="1.57079632679 0 0" xyz="0 -0.316 0"/>
    <parent link="panda_link2"/>
    <child link="panda_link3"/>
    <axis xyz="0 0 1"/>
    <limit effort="87" lower="-2.8973" upper="2.8973" velocity="2.1750"/>
    <dynamics damping="5.0" friction="2.0"/>
  </joint>

  <joint name="panda_joint4" type="revolute">
    <origin rpy="1.57079632679 0 0" xyz="0.0825 0 0"/>
    <parent link="panda_link3"/>
    <child link="panda_link4"/>
    <axis xyz="0 0 1"/>
    <limit effort="87" lower="-3.0718" upper="-0.0698" velocity="2.1750"/>
    <dynamics damping="1.0" friction="0.5"/>
  </joint>

  <joint name="panda_joint5" type="revolute">
    <origin rpy="-1.57079632679 0 0" xyz="-0.0825 0.384 0"/>
    <parent link="panda_link4"/>
    <child link="panda_link5"/>
    <axis xyz="0 0 1"/>
    <limit effort="12" lower="-2.8973" upper="2.8973" velocity="2.6100"/>
    <dynamics damping="2.0" friction="1.0"/>
  </joint>

  <joint name="panda_joint6" type="revolute">
    <origin rpy="1.57079632679 -1.57079632679 0" xyz="0 0 0"/>
    <parent link="panda_link5"/>
    <child link="panda_link6"/>
    <axis xyz="0 0 1"/>
    <limit effort="12" lower="-0.0175" upper="3.7525" velocity="2.6100"/>
    <dynamics damping="1.0" friction="0.5"/>
  </joint>

  <joint name="panda_joint7" type="revolute">
    <origin rpy="1.57079632679 -0.7854 0" xyz="0.088 0 0"/>
    <parent link="panda_link6"/>
    <child link="panda_link7"/>
    <axis xyz="0 0 1"/>
    <limit effort="12" lower="-2.8973" upper="2.8973" velocity="2.6100"/>
    <dynamics damping="1.0" friction="0.5"/>
  </joint>

  <joint name="panda_joint8" type="fixed">
    <origin rpy="0 0 -0.7854" xyz="0 0 0.107"/>
    <parent link="panda_link7"/>
    <child link="panda_link8"/>
    <axis xyz="0 0 0"/>
  </joint>

  <joint name="panda_hand_joint" type="fixed">
    <parent link="panda_link8"/>
    <child link="panda_hand"/>
    <origin rpy="0 0 0" xyz="0 0 0"/>
    <axis xyz="0 1 0"/>
  </joint>

  <joint name="gripper_frame_joint" type="fixed">
    <parent link="panda_link8"/>
    <child link="gripper_frame"/>
    <origin rpy="0 0 0" xyz="0 0 0.1034"/>
    <axis xyz="0 1 0"/>
  </joint>

  <joint name="panda_finger_joint1" type="prismatic">
    <parent link="panda_hand"/>
    <child link="panda_leftfinger"/>
    <origin rpy="0 0 0" xyz="0 0 0.0584"/>
    <axis xyz="0 1 0"/>
    <limit effort="20" lower="0.0" upper="0.04" velocity="0.2"/>
  </joint>

  <joint name="panda_finger_joint2" type="prismatic">
    <parent link="panda_hand"/>
    <child link="panda_rightfinger"/>
    <origin rpy="0 0 0" xyz="0 0 0.0584"/>
    <axis xyz="0 -1 0"/>
    <limit effort="20" lower="0.0" upper="0.04" velocity="0.2"/>
  </joint>

  <joint name="camera_joint" type="fixed">
    <parent link="panda_hand"/>
    <child link="camera_link"/>
    <origin rpy="0 0 -1.5708" xyz="0.055 0 0.04"/>
    <axis xyz="0 0 0"/>
  </joint>

  <joint name="Intel_rgb_camera_joint" type="fixed">
    <origin rpy="0 -1.5708 -1.5708" xyz="0 0 0"/>
    <parent link="camera_link"/>
    <child link="Intel_rgb_camera_link"/>
  </joint>

  <joint name="camera_joint_fake" type="fixed">
    <origin rpy="-1.5708 0 -1.5708 " xyz="0 0 0"/>
    <parent link="Intel_rgb_camera_link"/>
    <child link="camera_link_fake"/>
  </joint>

  <!-- //////////////////////   Transmissions  ////////////////////// -->
  <transmission name="left_front_wheel_joint_trans">
    <type>transmission_interface/SimpleTransmission</type>
    <actuator name="left_front_wheel_joint_motor">
      <mechanicalReduction>1</mechanicalReduction>
    </actuator>
    <joint name="left_front_wheel_joint">
      <hardwareInterface>hardware_interface/VelocityJointInterface</hardwareInterface>
    </joint>
  </transmission>
  <transmission name="right_front_wheel_joint_trans">
    <type>transmission_interface/SimpleTransmission</type>
    <actuator name="right_front_wheel_joint_motor">
      <mechanicalReduction>1</mechanicalReduction>
    </actuator>
    <joint name="right_front_wheel_joint">
      <hardwareInterface>hardware_interface/VelocityJointInterface</hardwareInterface>
    </joint>
  </transmission>
  <transmission name="left_rear_wheel_joint_trans">
    <type>transmission_interface/SimpleTransmission</type>
    <actuator name="left_rear_wheel_joint_motor">
      <mechanicalReduction>1</mechanicalReduction>
    </actuator>
    <joint name="left_rear_wheel_joint">
      <hardwareInterface>hardware_interface/VelocityJointInterface</hardwareInterface>
    </joint>
  </transmission>
  <transmission name="right_rear_wheel_joint_trans">
    <type>transmission_interface/SimpleTransmission</type>
    <actuator name="right_rear_wheel_joint_motor">
      <mechanicalReduction>1</mechanicalReduction>
    </actuator>
    <joint name="right_rear_wheel_joint">
      <hardwareInterface>hardware_interface/VelocityJointInterface</hardwareInterface>
    </joint>
  </transmission>

  <transmission name="panda_joint1_trans">
    <type>transmission_interface/SimpleTransmission</type>
    <actuator name="panda_joint1_motor">
      <hardwareInterface>hardware_interface/PositionJointInterface</hardwareInterface>
      <mechanicalReduction>1</mechanicalReduction>
    </actuator>
    <joint name="panda_joint1">
      <hardwareInterface>hardware_interface/PositionJointInterface</hardwareInterface>
    </joint>
  </transmission>
  <transmission name="panda_joint2_trans">
    <type>transmission_interface/SimpleTransmission</type>
    <actuator name="panda_joint2_motor">
      <hardwareInterface>hardware_interface/PositionJointInterface</hardwareInterface>
      <mechanicalReduction>1</mechanicalReduction>
    </actuator>
    <joint name="panda_joint2">
      <hardwareInterface>hardware_interface/PositionJointInterface</hardwareInterface>
    </joint>
  </transmission>
  <transmission name="panda_joint3_trans">
    <type>transmission_interface/SimpleTransmission</type>
    <actuator name="panda_joint3_motor">
      <hardwareInterface>hardware_interface/PositionJointInterface</hardwareInterface>
      <mechanicalReduction>1</mechanicalReduction>
    </actuator>
    <joint name="panda_joint3">
      <hardwareInterface>hardware_interface/PositionJointInterface</hardwareInterface>
    </joint>
  </transmission>
  <transmission name="panda_joint4_trans">
    <type>transmission_interface/SimpleTransmission</type>
    <actuator name="panda_joint4_motor">
      <hardwareInterface>hardware_interface/PositionJointInterface</hardwareInterface>
      <mechanicalReduction>1</mechanicalReduction>
    </actuator>
    <joint name="panda_joint4">
      <hardwareInterface>hardware_interface/PositionJointInterface</hardwareInterface>
    </joint>
  </transmission>
  <transmission name="panda_joint5_trans">
    <type>transmission_interface/SimpleTransmission</type>
    <actuator name="panda_joint5_motor">
      <hardwareInterface>hardware_interface/PositionJointInterface</hardwareInterface>
      <mechanicalReduction>1</mechanicalReduction>
    </actuator>
    <joint name="panda_joint5">
      <hardwareInterface>hardware_interface/PositionJointInterface</hardwareInterface>
    </joint>
  </transmission>
  <transmission name="panda_joint6_trans">
    <type>transmission_interface/SimpleTransmission</type>
    <actuator name="panda_joint6_motor">
      <hardwareInterface>hardware_interface/PositionJointInterface</hardwareInterface>
      <mechanicalReduction>1</mechanicalReduction>
    </actuator>
    <joint name="panda_joint6">
      <hardwareInterface>hardware_interface/PositionJointInterface</hardwareInterface>
    </joint>
  </transmission>
  <transmission name="panda_joint7_trans">
    <type>transmission_interface/SimpleTransmission</type>
    <actuator name="panda_joint7_motor">
      <hardwareInterface>hardware_interface/PositionJointInterface</hardwareInterface>
      <mechanicalReduction>1</mechanicalReduction>
    </actuator>
    <joint name="panda_joint7">
      <hardwareInterface>hardware_interface/PositionJointInterface</hardwareInterface>
    </joint>
  </transmission>
  <transmission name="panda_finger_joint1_trans">
    <type>transmission_interface/SimpleTransmission</type>
    <joint name="panda_finger_joint1">
      <hardwareInterface>hardware_interface/PositionJointInterface</hardwareInterface>
    </joint>
    <actuator name="panda_finger_joint1_motor">
      <hardwareInterface>hardware_interface/PositionJointInterface</hardwareInterface>
      <mechanicalReduction>1</mechanicalReduction>
    </actuator>
  </transmission>
  <transmission name="panda_finger_joint2_trans">
    <type>transmission_interface/SimpleTransmission</type>
    <joint name="panda_finger_joint2">
      <hardwareInterface>hardware_interface/PositionJointInterface</hardwareInterface>
    </joint>
    <actuator name="panda_finger_joint2_motor">
      <hardwareInterface>hardware_interface/PositionJointInterface</hardwareInterface>
      <mechanicalReduction>1</mechanicalReduction>
    </actuator>
  </transmission>

<!--######################################################################-->

  <gazebo>
    <plugin filename="libgazebo_ros_control.so" name="gazebo_ros_control">
      <robotNamespace>/</robotNamespace>
      <!-- <robotSimType>gazebo_ros_control/DefaultRobotHWSim</robotSimType> -->
      <legacyModeNS>true</legacyModeNS>
    </plugin>
  </gazebo>

  <gazebo>
    <plugin filename="libgazebo_ros_joint_state_publisher.so" name="panda_joint_state_publisher">
      <jointName>panda_joint1, panda_joint2, panda_joint3, panda_joint4, panda_joint5, panda_joint6, panda_joint7</jointName>
    </plugin>
  </gazebo>

  <gazebo>
    <plugin filename="libgazebo_grasp_fix.so" name="gazebo_grasp_fix">
      <arm>
        <arm_name>/</arm_name>
        <palm_link>panda_link7</palm_link>
        <gripper_link>panda_leftfinger</gripper_link>
        <gripper_link>panda_rightfinger</gripper_link>
      </arm>
      <forces_angle_tolerance>100</forces_angle_tolerance>
      <update_rate>30</update_rate>
      <grip_count_threshold>1</grip_count_threshold>
      <max_grip_count>3</max_grip_count>
      <release_tolerance>0.0005</release_tolerance>
      <disable_collisions_on_attach>true</disable_collisions_on_attach>
      <contact_topic>__default_topic__</contact_topic>
    </plugin>
  </gazebo>

  <gazebo>
    <plugin filename="libhector_gazebo_ros_imu.so" name="imu_controller">
      <robotNamespace>/</robotNamespace>
      <updateRate>50.0</updateRate>
      <bodyName>base_footprint</bodyName>
      <topicName>imu/data</topicName>
      <accelDrift>0.005 0.005 0.005</accelDrift>
      <accelGaussianNoise>0.005 0.005 0.005</accelGaussianNoise>
      <rateDrift>0.005 0.005 0.005 </rateDrift>
      <rateGaussianNoise>0.005 0.005 0.005 </rateGaussianNoise>
      <headingDrift>0.005</headingDrift>
      <headingGaussianNoise>0.005</headingGaussianNoise>
    </plugin>
  </gazebo>

  <gazebo reference="laser_link">
    <sensor name="laser" type="ray">
      <pose>0 0 0 0 0 0</pose>
      <visualize>true</visualize>
      <update_rate>40</update_rate>
      <ray>
        <scan>
          <horizontal>
            <samples>720</samples>
            <resolution>1</resolution>
            <min_angle>-1.5707963268</min_angle>
            <max_angle>1.5707963268</max_angle>
          </horizontal>
        </scan>
        <range>
          <min>0.10</min>
          <max>10.0</max>
          <resolution>0.01</resolution>
        </range>
        <noise>
          <type>gaussian</type>
          <mean>0.0</mean>
          <stddev>0.01</stddev>
        </noise>
      </ray>
      <plugin filename="libgazebo_ros_laser.so" name="rslidar_gazebo">
        <topicName>/scan</topicName>
        <frameName>laser_link</frameName>
      </plugin>
    </sensor>
  </gazebo>

  <gazebo reference="Intel_rgb_camera_link">
    <sensor name="camera" type="depth">
      <always_on>true</always_on>
      <update_rate>20.0</update_rate>
      <camera>
        <horizontal_fov>1.04719755</horizontal_fov>
        <image>
          <format>R8G8B8</format>
          <width>640</width>
          <height>480</height>
        </image>
        <clip>
          <near>0.05</near>
          <far>10.0</far>
        </clip>
      </camera>
      <plugin filename="libgazebo_ros_openni_kinect.so" name="Intel_depth_controller">
        <cameraName>camera</cameraName>
        <alwaysOn>true</alwaysOn>
        <updateRate>10</updateRate>
        <imageTopicName>rgb/image_raw</imageTopicName>
        <depthImageTopicName>depth/image_raw</depthImageTopicName>
        <pointCloudTopicName>depth/points</pointCloudTopicName>
        <cameraInfoTopicName>rgb/camera_info</cameraInfoTopicName>
        <depthImageCameraInfoTopicName>depth/camera_info</depthImageCameraInfoTopicName>
        <frameName>camera_link_fake</frameName>
        <baseline>0.1</baseline>
        <distortion_k1>0.0</distortion_k1>
        <distortion_k2>0.0</distortion_k2>
        <distortion_k3>0.0</distortion_k3>
        <distortion_t1>0.0</distortion_t1>
        <distortion_t2>0.0</distortion_t2>
        <pointCloudCutoff>0.4</pointCloudCutoff>
      </plugin>
    </sensor>
  </gazebo>

  <!-- //////////////////////   Gazebo parameters  ////////////////////// -->

  <!-- base_link -->
  <gazebo reference="base_link">
    <material>Gazebo/FlatBlack</material>
  </gazebo>
  <!-- top_plate_link -->
  <gazebo reference="top_plate_link">
    <material>Gazebo/Grey</material>
  </gazebo>
  <!-- rslidar_link -->
  <gazebo reference="rslidar_link">
    <material>Gazebo/DarkGrey</material>
  </gazebo>
  <!-- installation_plate_link -->
  <gazebo reference="installation_plate_link">
    <material>Gazebo/Black</material>
  </gazebo>

  <!-- box_link -->
  <gazebo reference="box_link">
    <material>Gazebo/Grey</material>
  </gazebo>

  <!-- left_front_wheel_link -->
  <gazebo reference="left_front_wheel_link">
    <mu1 value="1.0"/>
    <mu2 value="1.0"/>
    <kp value="10000000.0"/>
    <kd value="1.0"/>
    <fdir1 value="1 0 0"/>
    <material>Gazebo/DarkGrey</material>
  </gazebo>
  <!-- right_front_wheel_link -->
  <gazebo reference="right_front_wheel_link">
    <mu1 value="1.0"/>
    <mu2 value="1.0"/>
    <kp value="10000000.0"/>
    <kd value="1.0"/>
    <fdir1 value="1 0 0"/>
    <material>Gazebo/DarkGrey</material>
  </gazebo>
  <!-- left_rear_wheel_link -->
  <gazebo reference="left_rear_wheel_link">
    <mu1 value="1.0"/>
    <mu2 value="1.0"/>
    <kp value="10000000.0"/>
    <kd value="1.0"/>
    <fdir1 value="1 0 0"/>
    <material>Gazebo/DarkGrey</material>
  </gazebo>
  <!-- right_rear_wheel_link -->
  <gazebo reference="right_rear_wheel_link">
    <mu1 value="1.0"/>
    <mu2 value="1.0"/>
    <kp value="10000000.0"/>
    <kd value="1.0"/>
    <fdir1 value="1 0 0"/>
    <material>Gazebo/DarkGrey</material>
  </gazebo>

  <!-- panda_link0 -->
  <gazebo reference="panda_link0">
    <material>Gazebo/Grey</material>
    <mu1>0.61</mu1>
    <mu2>0.61</mu2>
  </gazebo>
  <!-- panda_link1 -->
  <gazebo reference="panda_link1">
    <material>Gazebo/White</material>
    <mu1>0.2</mu1>
    <mu2>0.2</mu2>
  </gazebo>
  <!-- panda_link2 -->
  <gazebo reference="panda_link2">
    <material>Gazebo/White</material>
    <mu1>0.2</mu1>
    <mu2>0.2</mu2>
  </gazebo>
  <!-- panda_link3 -->
  <gazebo reference="panda_link3">
    <material>Gazebo/White</material>
    <mu1>0.2</mu1>
    <mu2>0.2</mu2>
  </gazebo>
  <!-- panda_link4 -->
  <gazebo reference="panda_link4">
    <material>Gazebo/White</material>
    <mu1>0.2</mu1>
    <mu2>0.2</mu2>
  </gazebo>
  <!-- panda_link5 -->
  <gazebo reference="panda_link5">
    <material>Gazebo/White</material>
    <mu1>0.2</mu1>
    <mu2>0.2</mu2>
  </gazebo>
  <!-- panda_link6 -->
  <gazebo reference="panda_link6">
    <material>Gazebo/White</material>
    <mu1>0.2</mu1>
    <mu2>0.2</mu2>
  </gazebo>
  <!-- panda_link7 -->
  <gazebo reference="panda_link7">
    <material>Gazebo/Grey</material>
    <mu1>0.2</mu1>
    <mu2>0.2</mu2>
  </gazebo>
  <!-- panda_link8 -->
  <gazebo reference="panda_link8">
    <material>Gazebo/Grey</material>
    <mu1>0.2</mu1>
    <mu2>0.2</mu2>
  </gazebo>
  <!-- panda_hand -->
  <gazebo reference="panda_hand">
    <material>Gazebo/Grey</material>
    <mu1>0.2</mu1>
    <mu2>0.2</mu2>
  </gazebo>
  <!-- panda_leftfinger -->
  <gazebo reference="panda_leftfinger">
    <material>Gazebo/Grey</material>
    <mu1>2000.0</mu1>
    <mu2>1000.0</mu2>
    <kp>10000000.0</kp>
    <kd>1.0</kd>
  </gazebo>
  <!-- panda_rightfinger -->
  <gazebo reference="panda_rightfinger">
    <material>Gazebo/Grey</material>
    <mu1>2000.0</mu1>
    <mu2>1000.0</mu2>
    <kp>10000000.0</kp>
    <kd>1.0</kd>
  </gazebo>

</robot>
